Workbook
Name PED_CUM_MES: #REF!
Name PED_CUM_MES: #REF!
Name PED_CUM_MES: #REF!
Name VTA_ACUM_MES: #REF!
Name VTA_ACUM_MES: #REF!
Name VTA_ACUM_MES: #REF!

Sheet BD
A1: REGIONAL | B1: PEDIDO TUTI | C1: FECHA Y HORA | D1: CLIENTE | E1: VENDEDOR | F1: ESTADO | G1: VALOR | H1: ZONA | I1: RUTA
A2: MEDELLIN | B2: 105780 | C2: 45961.559 | D2: EDELIO DE JESUS VELEZ CORTES | E2: DUBY YARLENY BEDOYA FLOREZ 102 | F2: Procesada | G2: 6554.64 | H2: 102 | I2: 1306
A3: MEDELLIN | B3: 105781 | C3: 45961.561 | D3: EDWIN ARLEY BUILES RUA | E3: GEORLAN GARCIA PANIAGUA 117 | F3: Procesada | G3: 10793.95 | H3: 117 | I3: 1398
A4: MEDELLIN | B4: 105782 | C4: 45961.564 | D4: ADRIAN ARCANGEL ARROYAVE MUNERA | E4: GEORLAN GARCIA PANIAGUA 117 | F4: Procesada | G4: 56613.32 | H4: 117 | I4: 1398
A5: CUCUTA | B5: 105783 | C5: 45961.565 | D5: REINALDO TRIANA MUÑOZ | E5: FREDY ESTEPA 409 CUCUTA | F5: Procesada | G5: 12145.39 | H5: 409 | I5: 1674
A6: CUCUTA | B6: 105784 | C6: 45961.567 | D6: ISMENIA SERRANO VERGEL | E6: ZULY RANGEL GARCIA 413 CUCUTA | F6: Procesada | G6: 32850.82 | H6: 413 | I6: 1684
A7: MEDELLIN | B7: 105785 | C7: 45961.57 | D7: NOVIELA DEL SOCORRO VELEZ CORTES | E7: DUBY YARLENY BEDOYA FLOREZ 102 | F7: Procesada | G7: 21109.55 | H7: 102 | I7: 1306
A8: MEDELLIN | B8: 105786 | C8: 45961.573 | D8: RAUL OROZCO OROZCO | E8: KATHERINE GAVIRIA MAZO 103 | F8: Procesada | G8: 23086 | H8: 103 | I8: 1309
A9: BARRANQUILLA | B9: 105787 | C9: 45961.576 | D9: ISABEL ANGARITA SUAREZ | E9: JESUS ENRIQUE GIRALDO SOTO 714 BARRANQUILLA | F9: Procesada | G9: 31932.92 | H9: 714 | I9: 1940
A10: MEDELLIN | B10: 105788 | C10: 45961.581 | D10: DARIO ELEXANDER ROLDAN ZAPATA | E10: ELIANA GOMEZ 107 | F10: Procesada | G10: 24652.28 | H10: 107 | I10: 1321
A11: BARRANQUILLA | B11: 105789 | C11: 45961.582 | D11: YULEIMI PATRICIA PEREZ CABARCAS | E11: ALVARO ENRIQUE CASTAÑEDA MANJARRES 715 BARRANQUILLA | F11: Procesada | G11: 49336.6 | H11: 715 | I11: 1945
A12: PEREIRA | B12: 105790 | C12: 45961.586 | D12: JAIME DE JESUS PEREZ CARDONA | E12: LEONARDO RIOS HENAO 612 | F12: Procesada | G12: 28907.64 | H12: 612 | I12: 1834
A13: MONTERIA | B13: 105791 | C13: 45961.586 | D13: RUBIA ESTELA GARCIA MACEA | E13: JOSE GREGORIO OSTEN MERCADO 509 | F13: Procesada | G13: 28349.8 | H13: 509 | I13: 1737
... A619: MONTERIA | B619: 106446 | C619: 45965.997 | D619: ADELA GONZALEZ LONDOÑO | E619: NELSON ENRIQUE LOPEZ GONZALEZ 510 | F619: Procesada | G619: 9024.38 | H619: 510 | I619: 1714
A620: CUCUTA | B620: 106447 | C620: 2025-11-05 12:12:50 | D620: LUZ STELLA URIBE ORTIZ | E620: FREDY ESTEPA 409 CUCUTA | F620: Procesada | G620: 20911.227 | H620: 409 | I620: 1675
A621: BARRANQUILLA | B621: 106448 | C621: 2025-11-05 12:25:33 | D621: YESIR CARRASCAL MONTEJO | E621: MARIELA ESTER DE LEON 720 BARRANQUILLA | F621: Procesada | G621: 31932.916 | H621: 720 | I621: 1982
A622: BARRANQUILLA | B622: 106449 | C622: 2025-11-05 12:35:29 | D622: JOBANY DE JESUS ROA MARTINEZ | E622: MARIELA ESTER DE LEON 720 BARRANQUILLA | F622: Procesada | G622: 16806.798 | H622: 720 | I622: 1982
A623: BARRANQUILLA | B623: 106450 | C623: 2025-11-05 13:04:05 | D623: WILDER MARTINEZ MARTINEZ | E623: MARIELA ESTER DE LEON 720 BARRANQUILLA | F623: Procesada | G623: 8067.2437 | H623: 720 | I623: 1982
A624: BARRANQUILLA | B624: 106451 | C624: 2025-11-05 13:17:51 | D624: ROBERTO ENRIQUE PACHECO BARROS | E624: JESUS ENRIQUE GIRALDO SOTO 714 BARRANQUILLA | F624: Procesada | G624: 31932.916 | H624: 714 | I624: 1942
A625: CUCUTA | B625: 106452 | C625: 2025-11-05 13:21:11 | D625: LEONILDE CARRILLO PARRA | E625: MAIRA TORRES 411 CUCUTA | F625: Procesada | G625: 12983.193 | H625: 411 | I625: 1678
A626: MEDELLIN | B626: 106453 | C626: 2025-11-05 13:27:57 | D626: ANDRES JULIAN IDARRAGA SALAZAR | E626: GEORLAN GARCIA PANIAGUA 117 | F626: Procesada | G626: 11543 | H626: 117 | I626: 1398
A627: CUCUTA | B627: 106454 | C627: 2025-11-05 13:29:16 | D627: MARIA JULIA ANGEL DIEZ | E627: FREDY ESTEPA 409 CUCUTA | F627: Procesada | G627: 8542.0168 | H627: 409 | I627: 1675
A628: MONTERIA | B628: 106455 | C628: 2025-11-05 13:31:08 | D628: SVETLANA MARIA GONZALEZ DIAZ | E628: JOSE GREGORIO OSTEN MERCADO 509 | F628: Procesada | G628: 128333.7 | H628: 509 | I628: 1737
A629: BARRANQUILLA | B629: 106456 | C629: 2025-11-05 13:33:06 | D629: YADIRA DURAN LOPEZ | E629: STHEFANY OJITO BARRANQUILLA 712 | F629: Procesada | G629: 41290.496 | H629: 712 | I629: 1934
A630: CUCUTA | B630: 106457 | C630: 2025-11-05 13:34:13 | D630: DORIS AMPARO BURITICA DAZA | E630: ZULY RANGEL GARCIA 413 CUCUTA | F630: Procesada | G630: 28541.824 | H630: 413 | I630: 1684
A631: MEDELLIN | B631: 106459 | C631: 2025-11-05 13:35:30 | D631: JOHAN ANDRES CEBALLOS | E631: ELIANA GOMEZ 107 | F631: Procesada | G631: 31008.361 | H631: 107 | I631: 1321
... A1143: MEDELLIN | B1143: 106998 | C1143: 2025-11-06 18:16:52 | D1143: FRANCISCO IVAN TORO CARMONA | E1143: SEBASTIAN DIAZ VELEZ 105 | F1143: Procesada | G1143: 4078.1513 | H1143: 105 | I1143: 1314
A1144: MEDELLIN | B1144: 106999 | C1144: 2025-11-06 18:20:58 | D1144: ANA MARIA ORTIZ VILLA | F1144: Procesada | G1144: 126161.72 | H1144: 114 | I1144: 1343
A1145: BOGOTA | B1145: 107000 | C1145: 2025-11-06 18:24:17 | D1145: JOHN RONALD CUELLAR CAMACHO | E1145: CARLOS EDUARDO ROMERO 934 | F1145: Procesada | G1145: 41698.16 | H1145: 934 | I1145: 2196
A1146: BOGOTA | B1146: 107001 | C1146: 2025-11-06 18:25:39 | D1146: JOSE ALEJANDRO GUERRERO AVILA | E1146: MARIBEL REDONDO 918 | F1146: Procesada | G1146: 115927.63 | H1146: 918 | I1146: 2130
A1147: BOGOTA | B1147: 107002 | C1147: 2025-11-06 18:25:44 | D1147: JOSE ADOLFO FANDIÑO DIAZ | E1147: MONICA RODRIGUEZ RONCANCIO 946 | F1147: Procesada | G1147: 19845 | H1147: 946 | I1147: 2237
A1148: MEDELLIN | B1148: 107003 | C1148: 2025-11-06 18:29:18 | D1148: ASTRIS ELENA ESTRADA SERNA | E1148: ANDRES GRACIANO SERNA 104 | F1148: Procesada | G1148: 55868.723 | H1148: 104 | I1148: 1310
A1149: BOGOTA | B1149: 107004 | C1149: 2025-11-06 18:30:09 | D1149: JOSE ARBEY RAMIREZ YEPES | E1149: LEONARDO MANCERA BOLAÑOS 926 | F1149: Procesada | G1149: 20381.58 | H1149: 926 | I1149: 2158
A1150: VALLEDUPAR | B1150: 107005 | C1150: 2025-11-06 18:32:02 | D1150: ANDRES MAURICIO ESTRADA LOPEZ | E1150: LILIANA BLANCO LOPEZ 705 VALLEDUPAR | F1150: Procesada | G1150: 39117.58 | H1150: 705 | I1150: 1914
A1151: BOGOTA | B1151: 107006 | C1151: 2025-11-06 18:32:47 | D1151: ELVA LUCERO NUÑEZ CORREA | E1151: LEONARDO MANCERA BOLAÑOS 926 | F1151: Procesada | G1151: 35394.723 | H1151: 926 | I1151: 2158
A1152: BOGOTA | B1152: 107007 | C1152: 2025-11-06 18:34:08 | D1152: LUIS FERNANDO GUTIERREZ ESCOBAR | E1152: WILLIAM ALBERTO VELASQUEZ BERNAL 920 | F1152: Procesada | G1152: 139080 | H1152: 920 | I1152: 2136
A1153: BOGOTA | B1153: 107008 | C1153: 2025-11-06 18:34:11 | D1153: CARLOS JULIO SUAREZ CELIS | E1153: LEONARDO MANCERA BOLAÑOS 926 | F1153: Procesada | G1153: 31932.84 | H1153: 926 | I1153: 2158
A1154: BOGOTA | B1154: 107009 | C1154: 2025-11-06 18:35:24 | D1154: MARIA GILMA ECHEVERRI CEBALLOS | E1154: LEONARDO MANCERA BOLAÑOS 926 | F1154: Procesada | G1154: 15504.176 | H1154: 926 | I1154: 2158
A1155: BOGOTA | B1155: 107010 | C1155: 2025-11-06 18:36:22 | D1155: MARIA BARBARA MORA VARGAS | E1155: LEONARDO MANCERA BOLAÑOS 926 | F1155: Procesada | G1155: 16806.798 | H1155: 926 | I1155: 2158
A1156: BOGOTA | B1156: 107011 | C1156: 2025-11-06 18:36:34 | D1156: MARTHA LUISA SALDAÑA NOVA | E1156: WILSON JAVIER MONTAÑEZ MARTINEZ 923 | F1156: Procesada | G1156: 16806.798 | H1156: 923 | I1156: 2149
...

Sheet BD VENTAS TERCEROS
A1: Fecha | B1: Factura | C1: Número de producto | D1: ProductName | E1: Concat Referencia | F1: Cantidad | G1: Precio unitario | H1: LineTotalDiscountAmount | I1: Importe | J1: Almacén | K1: Und Negocio | L1: Centro de Costos | M1: Nombre CC | N1: Regional | O1: Tipo Producto | P1: Semana | Q1: Ruta | R1: Zona | S1: Dia | T1: Referencia | U1: Cant Multiplicar | V1: Cantidad Real | W1: Canal | X1: Cliente | Y1: Tipo de Venta | Z1: Documento del Cliente | AA1: Cedula Vendedor | AB1: Nombre de Entrega
A2: 45965 | B2: HHBQ000722628 | C2: YACAN50 | D2: CANDADO 50 MM | E2: YACAN50 - CANDADO 50 MM | F2: 2 | G2: 4327.73 | H2: 0 | I2: 8655.46 | J2: VLL04 | K2: 1 | L2: 213 | M2: Tuti Valledupar | N2: ZONA NORTE | O2: TERCEROS | P2: 2025 SEM 45 | Q2: 1917 | R2: 706 | S2: martes | T2: YASS | U2: 1 | V2: 2 | W2: TAT | X2: ISRAELA MATILDE AMAYA IGUARAN | Y2: Preventa | Z2: 40791787 | AA2: 49794720 | AB2: DOÑA MATI
A3: 45965 | B3: HHMO000623487 | C3: LYLIMPLAV200DX1 | D3: LIMPIAYA LIMPIADOR LAVANDA 200 ML X1 | E3: LYLIMPLAV200DX1 - LIMPIAYA LIMPIADOR LAVANDA 200 ML X1 | F3: 6 | G3: 1120 | H3: 0 | I3: 6720 | J3: MT11 | K3: 1 | L3: 156 | M3: TUTI Monteria | N3: ZONA CENTRO | O3: TERCEROS | P3: 2025 SEM 45 | Q3: 1714 | R3: 510 | S3: martes | T3: ETERNA | U3: 1 | V3: 6 | W3: TAT | X3: SAMIR DAVID ARRIETA HERNANDEZ | Y3: Preventa | Z3: 1002997934 | AA3: 1067887069 | AB3: TIENDA LA COLMENA
A4: 45965 | B4: HHME001459620 | C4: PBDESCOJINX18 | D4: DES. AFM DPL ORIG 12G X18 | E4: PBDESCOJINX18 - DES. AFM DPL ORIG 12G X18 | F4: 2 | G4: 11900 | H4: 714 | I4: 23086 | J4: MD06 | K4: 1 | L4: 125 | M4: TUTI Medellin | N4: ZONA CENTRO | O4: TERCEROS | P4: 2025 SEM 45 | Q4: 1398 | R4: 117 | S4: martes | T4: PREBEL | U4: 1 | V4: 2 | W4: TAT | X4: ADRIAN ARCANGEL ARROYAVE MUNERA | Y4: Preventa | Z4: 8156669 | AA4: 8432406 | AB4: LA VENTANITA
A5: 45965 | B5: HHME001459620 | C5: LYESPOOROX12 | D5: LIMPIAYA ESPONJA ORO/PLATA X12 | E5: LYESPOOROX12 - LIMPIAYA ESPONJA ORO/PLATA X12 | F5: 2 | G5: 8991.6 | H5: 899.16 | I5: 17084.04 | J5: MD06 | K5: 1 | L5: 125 | M5: TUTI Medellin | N5: ZONA CENTRO | O5: TERCEROS | P5: 2025 SEM 45 | Q5: 1398 | R5: 117 | S5: martes | T5: ETERNA | U5: 1 | V5: 2 | W5: TAT | X5: ADRIAN ARCANGEL ARROYAVE MUNERA | Y5: Preventa | Z5: 8156669 | AA5: 8432406 | AB5: LA VENTANITA
A6: 45965 | B6: HHME001459620 | C6: YAPANIAZU | D6: PAÑITOS HUMEDOS DAMPY X 20 AZUL | E6: YAPANIAZU - PAÑITOS HUMEDOS DAMPY X 20 AZUL | F6: 5 | G6: 1344.54 | H6: 0 | I6: 6722.7 | J6: MD06 | K6: 1 | L6: 125 | M6: TUTI Medellin | N6: ZONA CENTRO | O6: TERCEROS | P6: 2025 SEM 45 | Q6: 1398 | R6: 117 | S6: martes | T6: YASS | U6: 1 | V6: 5 | W6: TAT | X6: ADRIAN ARCANGEL ARROYAVE MUNERA | Y6: Preventa | Z6: 8156669 | AA6: 8432406 | AB6: LA VENTANITA
A7: 45965 | B7: HHME001459620 | C7: YAPADAM150 | D7: PAÑITOS HUMEDOS DAMPY X 150 UND AZUL | E7: YAPADAM150 - PAÑITOS HUMEDOS DAMPY X 150 UND AZUL | F7: 2 | G7: 6422.4 | H7: 0 | I7: 12844.8 | J7: MD06 | K7: 1 | L7: 125 | M7: TUTI Medellin | N7: ZONA CENTRO | O7: TERCEROS | P7: 2025 SEM 45 | Q7: 1398 | R7: 117 | S7: martes | T7: YASS | U7: 1 | V7: 2 | W7: TAT | X7: ADRIAN ARCANGEL ARROYAVE MUNERA | Y7: Preventa | Z7: 8156669 | AA7: 8432406 | AB7: LA VENTANITA
A8: 45965 | B8: HHBO001170394 | C8: LYLOZA700DX1 | D8: LIMPIAYA LAVA LOZA DOYPACK 700 ML X1 | E8: LYLOZA700DX1 - LIMPIAYA LAVA LOZA DOYPACK 700 ML X1 | F8: 1 | G8: 3562.19 | H8: 0 | I8: 3562.19 | J8: BG13 | K8: 1 | L8: 126 | M8: TUTI Bogota | N8: ZONA BOGOTA | O8: TERCEROS | P8: 2025 SEM 45 | Q8: 2209 | R8: 938 | S8: martes | T8: ETERNA | U8: 1 | V8: 1 | W8: TAT | X8: SIERVO ALONSO PEREZ RODRIGUEZ | Y8: Preventa | Z8: 1074415224 | AA8: 1016001588 | AB8: PAPELERIA BOTICA DE EMANUEL
A9: 45965 | B9: HHBO001170394 | C9: LYDETE1800DX1 | D9: DETERGENTE ETERNA DOYPACK 1800 ML X1 | E9: LYDETE1800DX1 - DETERGENTE ETERNA DOYPACK 1800 ML X1 | F9: 1 | G9: 12000 | H9: 0 | I9: 12000 | J9: BG13 | K9: 1 | L9: 126 | M9: TUTI Bogota | N9: ZONA BOGOTA | O9: TERCEROS | P9: 2025 SEM 45 | Q9: 2209 | R9: 938 | S9: martes | T9: ETERNA | U9: 1 | V9: 1 | W9: TAT | X9: SIERVO ALONSO PEREZ RODRIGUEZ | Y9: Preventa | Z9: 1074415224 | AA9: 1016001588 | AB9: PAPELERIA BOTICA DE EMANUEL
A10: 45965 | B10: HHME001459642 | C10: YAVABY20GR | D10: VASELINA BABY, 20 GRAMOS, MARCA JUHNIOS | E10: YAVABY20GR - VASELINA BABY, 20 GRAMOS, MARCA JUHNIOS | F10: 6 | G10: 1444 | H10: 0 | I10: 8664 | J10: MD02 | K10: 1 | L10: 125 | M10: TUTI Medellin | N10: ZONA CENTRO | O10: TERCEROS | P10: 2025 SEM 45 | Q10: 1345 | R10: 116 | S10: martes | T10: YASS | U10: 1 | V10: 6 | W10: TAT | X10: LUIS ALFONSO ZAPATA TAPIAS | Y10: Preventa | Z10: 71700770 | AA10: 71381318 | AB10: LA TIENDA DE LUCHO
A11: 45965 | B11: HHME001459689 | C11: DRDESOPIES | D11: DESODORANTE PARA PIES | E11: DRDESOPIES - DESODORANTE PARA PIES | F11: 1 | G11: 9636 | H11: 0 | I11: 9636 | J11: MD30 | K11: 1 | L11: 1 | M11: MEDELLIN | N11: ZONA CENTRO | O11: TERCEROS | P11: 2025 SEM 45 | Q11: 1338 | R11: 115 | S11: martes | T11: DROMATIC | U11: 1 | V11: 1 | W11: TAT | X11: MARILENI VELASQUEZ PEREZ | Y11: Preventa | Z11: 44007369 | AA11: 1036639459 | AB11: GRANERO EL VECINO
A12: 45965 | B12: HHBQ000722645 | C12: YACAN50 | D12: CANDADO 50 MM | E12: YACAN50 - CANDADO 50 MM | F12: 2 | G12: 4327.73 | H12: 0 | I12: 8655.46 | J12: VLL04 | K12: 1 | L12: 213 | M12: Tuti Valledupar | N12: ZONA NORTE | O12: TERCEROS | P12: 2025 SEM 45 | Q12: 1916 | R12: 706 | S12: martes | T12: YASS | U12: 1 | V12: 2 | W12: TAT | X12: ANA EDILZA SANCHEZ PEREZ | Y12: Preventa | Z12: 60330338 | AA12: 49794720 | AB12: PROVISIONES BRENDA
A13: 45965 | B13: HHBQ000722645 | C13: YACAN38 | D13: CANDADO 38 MM | E13: YACAN38 - CANDADO 38 MM | F13: 2 | G13: 2668.75 | H13: 0 | I13: 5337.5 | J13: VLL04 | K13: 1 | L13: 213 | M13: Tuti Valledupar | N13: ZONA NORTE | O13: TERCEROS | P13: 2025 SEM 45 | Q13: 1916 | R13: 706 | S13: martes | T13: YASS | U13: 1 | V13: 2 | W13: TAT | X13: ANA EDILZA SANCHEZ PEREZ | Y13: Preventa | Z13: 60330338 | AA13: 49794720 | AB13: PROVISIONES BRENDA
... A83: 45965 | B83: HHBO001170461 | C83: YAGOM90 | D83: GOMINA N17 EN SOBRE 90G | E83: YAGOM90 - GOMINA N17 EN SOBRE 90G | F83: 1 | G83: 1092.44 | H83: 0 | I83: 1092.44 | J83: BG22 | K83: 1 | L83: 126 | M83: TUTI Bogota | N83: ZONA BOGOTA | O83: TERCEROS | P83: 2025 SEM 45 | Q83: 2130 | R83: 918 | S83: martes | T83: YASS | U83: 1 | V83: 1 | W83: TAT | X83: ANGELA CRUZ CAMACHO | Y83: Preventa | Z83: 53074221 | AA83: 22639797 | AB83: MINIMARKET PLUS
A84: 45965 | B84: HHME001459766 | C84: YALAPIZAMAX12 | D84: LAPIZ ESCOLAR AMARILLO X12 | E84: YALAPIZAMAX12 - LAPIZ ESCOLAR AMARILLO X12 | F84: 1 | G84: 4853 | H84: 0 | I84: 4853 | J84: MD01 | K84: 1 | L84: 125 | M84: TUTI Medellin | N84: ZONA CENTRO | O84: TERCEROS | P84: 2025 SEM 45 | Q84: 1342 | R84: 114 | S84: martes | T84: 0 | U84: 1 | V84: 1 | W84: TAT | X84: MARIA ESTELA CIRO CASTAÑO | Y84: Preventa | Z84: 43069565 | AA84: 1039023085 | AB84: LA MANO DE DIOS
A85: 45965 | B85: HHME001459766 | C85: YALAPIROX12 | D85: LAPIZ ROJO X12 UND | E85: YALAPIROX12 - LAPIZ ROJO X12 UND | F85: 1 | G85: 4882 | H85: 0 | I85: 4882 | J85: MD01 | K85: 1 | L85: 125 | M85: TUTI Medellin | N85: ZONA CENTRO | O85: TERCEROS | P85: 2025 SEM 45 | Q85: 1342 | R85: 114 | S85: martes | T85: YASS | U85: 1 | V85: 1 | W85: TAT | X85: MARIA ESTELA CIRO CASTAÑO | Y85: Preventa | Z85: 43069565 | AA85: 1039023085 | AB85: LA MANO DE DIOS
A86: 45965 | B86: HHCA000425934 | C86: YACONDSEX | D86: CONDONES X3 UNIDADES ECONOMICO | E86: YACONDSEX - CONDONES X3 UNIDADES ECONOMICO | F86: 20 | G86: 866.2 | H86: 0 | I86: 17324 | J86: CL07 | K86: 1 | L86: 171 | M86: TUTI Cali | N86: ZONA SUR | O86: TERCEROS | P86: 2025 SEM 45 | Q86: 1878 | R86: 620 | S86: martes | T86: YASS | U86: 1 | V86: 20 | W86: TAT | X86: YORMAN SANTIAGO LOPEZ CARDONA | Y86: Preventa | Z86: 1108252886 | AA86: 1143845966 | AB86: SUPERMERCADO 4 ESQUINAS
A87: 45965 | B87: HHCA000425934 | C87: YASEDA20 | D87: SEDA DENTAL CON CERA 20 MT | E87: YASEDA20 - SEDA DENTAL CON CERA 20 MT | F87: 20 | G87: 1092.44 | H87: 0 | I87: 21848.8 | J87: CL07 | K87: 1 | L87: 171 | M87: TUTI Cali | N87: ZONA SUR | O87: TERCEROS | P87: 2025 SEM 45 | Q87: 1878 | R87: 620 | S87: martes | T87: YASS | U87: 1 | V87: 20 | W87: TAT | X87: YORMAN SANTIAGO LOPEZ CARDONA | Y87: Preventa | Z87: 1108252886 | AA87: 1143845966 | AB87: SUPERMERCADO 4 ESQUINAS
A88: 45965 | B88: HHME001459853 | C88: PDELLAECONX10 | D88: ELLAS ECONOMICA X 10 | E88: PDELLAECONX10 - ELLAS ECONOMICA X 10 | F88: 5 | G88: 2544 | H88: 1272 | I88: 11448 | J88: TT02 | K88: 1 | L88: 125 | M88: TUTI Medellin | N88: ZONA CENTRO | O88: TERCEROS | P88: 2025 SEM 45 | Q88: 1321 | R88: 107 | S88: martes | T88: PRODUSA | U88: 1 | V88: 5 | W88: TAT | X88: JAVIER LEON ARISTIZBAL HOYOS | Y88: Preventa | Z88: 70383361 | AA88: 1037949442 | AB88: MI TIENDITA
A89: 45965 | B89: HHME001459853 | C89: PDTOAVEN60X8 | D89: VENUS DELGADA PACA 60 X 8 | E89: PDTOAVEN60X8 - VENUS DELGADA PACA 60 X 8 | F89: 5 | G89: 1718 | H89: 859 | I89: 7731 | J89: TT02 | K89: 1 | L89: 125 | M89: TUTI Medellin | N89: ZONA CENTRO | O89: TERCEROS | P89: 2025 SEM 45 | Q89: 1321 | R89: 107 | S89: martes | T89: PRODUSA | U89: 1 | V89: 5 | W89: TAT | X89: JAVIER LEON ARISTIZBAL HOYOS | Y89: Preventa | Z89: 70383361 | AA89: 1037949442 | AB89: MI TIENDITA
A90: 45965 | B90: HHME001459853 | C90: KNLIMTEN | D90: LIMPIADOR DE TENNIS KNIGHT | E90: KNLIMTEN - LIMPIADOR DE TENNIS KNIGHT | F90: 1 | G90: 6350 | H90: 635 | I90: 5715 | J90: TT02 | K90: 1 | L90: 125 | M90: TUTI Medellin | N90: ZONA CENTRO | O90: TERCEROS | P90: 2025 SEM 45 | Q90: 1321 | R90: 107 | S90: martes | T90: KNIGHT | U90: 1 | V90: 1 | W90: TAT | X90: JAVIER LEON ARISTIZBAL HOYOS | Y90: Preventa | Z90: 70383361 | AA90: 1037949442 | AB90: MI TIENDITA
A91: 45965 | B91: HHME001459853 | C91: YAGOM90 | D91: GOMINA N17 EN SOBRE 90G | E91: YAGOM90 - GOMINA N17 EN SOBRE 90G | F91: 3 | G91: 1092.44 | H91: 0 | I91: 3277.32 | J91: TT02 | K91: 1 | L91: 125 | M91: TUTI Medellin | N91: ZONA CENTRO | O91: TERCEROS | P91: 2025 SEM 45 | Q91: 1321 | R91: 107 | S91: martes | T91: YASS | U91: 1 | V91: 3 | W91: TAT | X91: JAVIER LEON ARISTIZBAL HOYOS | Y91: Preventa | Z91: 70383361 | AA91: 1037949442 | AB91: MI TIENDITA
A92: 45965 | B92: HHBO001170571 | C92: YACAN63 | D92: CANDADO 63 MM | E92: YACAN63 - CANDADO 63 MM | F92: 1 | G92: 5940 | H92: 0 | I92: 5940 | J92: BG13 | K92: 1 | L92: 2 | M92: CIUDAD BOGOTA | N92: ZONA BOGOTA | O92: TERCEROS | P92: 2025 SEM 45 | Q92: 2234 | R92: 945 | S92: martes | T92: YASS | U92: 1 | V92: 1 | W92: TAT | X92: DIANA CATALINA CORREDOR PRIETO | Y92: Preventa | Z92: 1012387423 | AA92: 52460170 | AB92: MINIMARKET ROY
A93: 45965 | B93: HHBO001170578 | C93: YACONDSEX | D93: CONDONES X3 UNIDADES ECONOMICO | E93: YACONDSEX - CONDONES X3 UNIDADES ECONOMICO | F93: 3 | G93: 866.2 | H93: 0 | I93: 2598.6 | J93: BG23 | K93: 1 | L93: 166 | M93: VILLAVICENCIO | N93: ZONA BOGOTA | O93: TERCEROS | P93: 2025 SEM 45 | Q93: 2910 | R93: 905 | S93: martes | T93: YASS | U93: 1 | V93: 3 | W93: TAT | X93: BLANCA CECILIA RODRIGUEZ DUARTE | Y93: Preventa | Z93: 41655922 | AA93: 86065145 | AB93: EL ESQUINAZO J30
A94: 45965 | B94: HHBO001170578 | C94: YAPANIAZUX12 | D94: PAÑITOS HUMEDOS DAMPY AAZUL X 12UND | E94: YAPANIAZUX12 - PAÑITOS HUMEDOS DAMPY AAZUL X 12UND | F94: 6 | G94: 870 | H94: 0 | I94: 5220 | J94: BG23 | K94: 1 | L94: 166 | M94: VILLAVICENCIO | N94: ZONA BOGOTA | O94: TERCEROS | P94: 2025 SEM 45 | Q94: 2910 | R94: 905 | S94: martes | T94: YASS | U94: 1 | V94: 6 | W94: TAT | X94: BLANCA CECILIA RODRIGUEZ DUARTE | Y94: Preventa | Z94: 41655922 | AA94: 86065145 | AB94: EL ESQUINAZO J30
A95: 45965 | B95: HHBQ000722805 | C95: YACAN38 | D95: CANDADO 38 MM | E95: YACAN38 - CANDADO 38 MM | F95: 6 | G95: 2668.75 | H95: 0 | I95: 16012.5 | J95: BQ15 | K95: 1 | L95: 212 | M95: Tuti Cartagena | N95: ZONA NORTE | O95: TERCEROS | P95: 2025 SEM 45 | Q95: 1959 | R95: 718 | S95: martes | T95: YASS | U95: 1 | V95: 6 | W95: TAT | X95: ROSA URBINA GUTIERREZ PEÑARANDA | Y95: Preventa | Z95: 30882589 | AA95: 1044921552 | AB95: TIENDA Y VARIEDAD ROCHY
A96: 45965 | B96: HHBQ000722805 | C96: YACAN50 | D96: CANDADO 50 MM | E96: YACAN50 - CANDADO 50 MM | F96: 4 | G96: 4327.73 | H96: 0 | I96: 17310.92 | J96: BQ15 | K96: 1 | L96: 212 | M96: Tuti Cartagena | N96: ZONA NORTE | O96: TERCEROS | P96: 2025 SEM 45 | Q96: 1959 | R96: 718 | S96: martes | T96: YASS | U96: 1 | V96: 4 | W96: TAT | X96: ROSA URBINA GUTIERREZ PEÑARANDA | Y96: Preventa | Z96: 30882589 | AA96: 1044921552 | AB96: TIENDA Y VARIEDAD ROCHY
... A112: 45965 | B112: HHBO001170558 | C112: LYDETE3X1800 | D112: COMBO DETERGENTE ETERNA 3.000+1.800 OFERTA | E112: LYDETE3X1800 - COMBO DETERGENTE ETERNA 3.000+1.800 OFERTA | F112: 1 | G112: 28655.46 | H112: 0 | I112: 28655.46 | J112: BG23 | K112: 1 | L112: 166 | M112: VILLAVICENCIO | N112: ZONA BOGOTA | O112: TERCEROS | P112: 2025 SEM 45 | Q112: 2911 | R112: 905 | S112: martes | T112: ETERNA | U112: 1 | V112: 1 | W112: TAT | X112: CARLOS IVAN ROJAS CANO | Y112: Preventa | Z112: 1123801553 | AA112: 86065145 | AB112: TIENDA EL GORDO
A113: 45965 | B113: HHME001459888 | C113: YALAPIZAMAX12 | D113: LAPIZ ESCOLAR AMARILLO X12 | E113: YALAPIZAMAX12 - LAPIZ ESCOLAR AMARILLO X12 | F113: 1 | G113: 4853 | H113: 0 | I113: 4853 | J113: MD04 | K113: 1 | L113: 125 | M113: TUTI Medellin | N113: ZONA CENTRO | O113: TERCEROS | P113: 2025 SEM 45 | Q113: 1306 | R113: 102 | S113: martes | T113: 0 | U113: 1 | V113: 1 | W113: TAT | X113: MARIA ELCY VARGAS MARIN | Y113: Preventa | Z113: 55056060 | AA113: 1036660589 | AB113: TIENDA SAMU
A114: 45965 | B114: HHME001459896 | C114: YAGOM90 | D114: GOMINA N17 EN SOBRE 90G | E114: YAGOM90 - GOMINA N17 EN SOBRE 90G | F114: 12 | G114: 1092.44 | H114: 0 | I114: 13109.28 | J114: MD02 | K114: 1 | L114: 125 | M114: TUTI Medellin | N114: ZONA CENTRO | O114: TERCEROS | P114: 2025 SEM 45 | Q114: 1398 | R114: 117 | S114: martes | T114: YASS | U114: 1 | V114: 12 | W114: TAT | X114: HAROL CASTRILLON GOMEZ | Y114: Preventa | Z114: 1003757794 | AA114: 8432406 | AB114: MILAGROS LA 38
A115: 45965 | B115: HHME001459940 | C115: PBDESCOJINX18 | D115: DES. AFM DPL ORIG 12G X18 | E115: PBDESCOJINX18 - DES. AFM DPL ORIG 12G X18 | F115: 1 | G115: 11900 | H115: 357 | I115: 11543 | J115: MD06 | K115: 1 | L115: 125 | M115: TUTI Medellin | N115: ZONA CENTRO | O115: TERCEROS | P115: 2025 SEM 45 | Q115: 1309 | R115: 103 | S115: martes | T115: PREBEL | U115: 1 | V115: 1 | W115: TAT | X115: JOSE ANTONIO YARCE RAIGOSA | Y115: Preventa | Z115: 4391768 | AA115: 1037594291 | AB115: GRANERO NELSON
A116: 45965 | B116: HHBO001170607 | C116: YALAPIZAMAX12 | D116: LAPIZ ESCOLAR AMARILLO X12 | E116: YALAPIZAMAX12 - LAPIZ ESCOLAR AMARILLO X12 | F116: 1 | G116: 4853 | H116: 0 | I116: 4853 | J116: BG13 | K116: 1 | L116: 126 | M116: TUTI Bogota | N116: ZONA BOGOTA | O116: TERCEROS | P116: 2025 SEM 45 | Q116: 2234 | R116: 945 | S116: martes | T116: 0 | U116: 1 | V116: 1 | W116: TAT | X116: NUBIA JANET CONTRERAS ARIAS | Y116: Preventa | Z116: 51899379 | AA116: 52460170 | AB116: BAVIERA EXPRESS
A117: 45965 | B117: HHBO001170607 | C117: YALAPIROX12 | D117: LAPIZ ROJO X12 UND | E117: YALAPIROX12 - LAPIZ ROJO X12 UND | F117: 1 | G117: 4882 | H117: 0 | I117: 4882 | J117: BG13 | K117: 1 | L117: 126 | M117: TUTI Bogota | N117: ZONA BOGOTA | O117: TERCEROS | P117: 2025 SEM 45 | Q117: 2234 | R117: 945 | S117: martes | T117: YASS | U117: 1 | V117: 1 | W117: TAT | X117: NUBIA JANET CONTRERAS ARIAS | Y117: Preventa | Z117: 51899379 | AA117: 52460170 | AB117: BAVIERA EXPRESS
A118: 45965 | B118: HHBO001170607 | C118: YASEDA20 | D118: SEDA DENTAL CON CERA 20 MT | E118: YASEDA20 - SEDA DENTAL CON CERA 20 MT | F118: 6 | G118: 1092.44 | H118: 0 | I118: 6554.64 | J118: BG13 | K118: 1 | L118: 126 | M118: TUTI Bogota | N118: ZONA BOGOTA | O118: TERCEROS | P118: 2025 SEM 45 | Q118: 2234 | R118: 945 | S118: martes | T118: YASS | U118: 1 | V118: 6 | W118: TAT | X118: NUBIA JANET CONTRERAS ARIAS | Y118: Preventa | Z118: 51899379 | AA118: 52460170 | AB118: BAVIERA EXPRESS
A119: 45965 | B119: HHBO001170607 | C119: YAPANIAMA | D119: PAÑITOS HUMEDOS DAMPY AMARILLOS X 15 UND | E119: YAPANIAMA - PAÑITOS HUMEDOS DAMPY AMARILLOS X 15 UND | F119: 6 | G119: 1260.5 | H119: 0 | I119: 7563 | J119: BG13 | K119: 1 | L119: 126 | M119: TUTI Bogota | N119: ZONA BOGOTA | O119: TERCEROS | P119: 2025 SEM 45 | Q119: 2234 | R119: 945 | S119: martes | T119: YASS | U119: 1 | V119: 6 | W119: TAT | X119: NUBIA JANET CONTRERAS ARIAS | Y119: Preventa | Z119: 51899379 | AA119: 52460170 | AB119: BAVIERA EXPRESS
A120: 45965 | B120: HHBO001170609 | C120: LYDETE1800DX1 | D120: DETERGENTE ETERNA DOYPACK 1800 ML X1 | E120: LYDETE1800DX1 - DETERGENTE ETERNA DOYPACK 1800 ML X1 | F120: 1 | G120: 12000 | H120: 0 | I120: 12000 | J120: BG13 | K120: 1 | L120: 2 | M120: CIUDAD BOGOTA | N120: ZONA BOGOTA | O120: TERCEROS | P120: 2025 SEM 45 | Q120: 2234 | R120: 945 | S120: martes | T120: ETERNA | U120: 1 | V120: 1 | W120: TAT | X120: BRYAN ALEXANDER RAMOS RODRIGUEZ | Y120: Preventa | Z120: 1022948813 | AA120: 52460170 | AB120: BRAYAN RAMOS
A121: 45965 | B121: HHME001459999 | C121: YABOLSAMED | D121: BOLSA BASURA PAQUETE X8 UNIDADES | E121: YABOLSAMED - BOLSA BASURA PAQUETE X8 UNIDADES | F121: 12 | G121: 1344.54 | H121: 0 | I121: 16134.48 | J121: MD01 | K121: 1 | L121: 125 | M121: TUTI Medellin | N121: ZONA CENTRO | O121: TERCEROS | P121: 2025 SEM 45 | Q121: 1333 | R121: 113 | S121: martes | T121: YASS | U121: 1 | V121: 12 | W121: TAT | X121: FABIO HURTADO BERMUDEZ | Y121: Preventa | Z121: 71664546 | AA121: 79389221 | AB121: FABIO HURTADO BERMUDEZ
A122: 45965 | B122: HHME001460006 | C122: YABOLSAMED | D122: BOLSA BASURA PAQUETE X8 UNIDADES | E122: YABOLSAMED - BOLSA BASURA PAQUETE X8 UNIDADES | F122: 30 | G122: 1344.54 | H122: 0 | I122: 40336.2 | J122: MD01 | K122: 1 | L122: 125 | M122: TUTI Medellin | N122: ZONA CENTRO | O122: TERCEROS | P122: 2025 SEM 45 | Q122: 1333 | R122: 113 | S122: martes | T122: YASS | U122: 1 | V122: 30 | W122: TAT | X122: VICTOR JAIME ECHEVERRI GONZALEZ | Y122: Preventa | Z122: 3563520 | AA122: 79389221 | AB122: VICTOR JAIME ECHEVERRI GONZALEZ
A123: 45965 | B123: HHBO001170618 | C123: PBTAL85X2 | D123: TALCO 85GR X 2 | E123: PBTAL85X2 - TALCO 85GR X 2 | F123: 1 | G123: 12290.73 | H123: 0 | I123: 12290.73 | J123: BG23 | K123: 1 | L123: 166 | M123: VILLAVICENCIO | N123: ZONA BOGOTA | O123: TERCEROS | P123: 2025 SEM 45 | Q123: 2910 | R123: 905 | S123: martes | T123: PREBEL | U123: 1 | V123: 1 | W123: TAT | X123: FRANCISCO CELY PALACIOS | Y123: Preventa | Z123: 17335606 | AA123: 86065145 | AB123: AUTOSERVICIO EL ALTO
A124: 45965 | B124: HHBU000696923 | C124: LYSUAV190DX1 | D124: LIMPIAYA SUAVIZANTE DOYPACK 190 ML X1 | E124: LYSUAV190DX1 - LIMPIAYA SUAVIZANTE DOYPACK 190 ML X1 | F124: 6 | G124: 977 | H124: 0 | I124: 5862 | J124: CU02 | K124: 1 | L124: 211 | M124: Tuti Cúcuta | N124: ZONA SANTANDER | O124: TERCEROS | P124: 2025 SEM 45 | Q124: 1675 | R124: 409 | S124: martes | T124: ETERNA | U124: 1 | V124: 6 | W124: TAT | X124: ANGELA DANIELA VILLEGAS CACERES | Y124: Preventa | Z124: 1092339092 | AA124: 1090387974 | AB124: TIENDA MIXTA PANDA
...

Sheet VENTA TERCEROS
A3: Etiquetas de fila | B3: Suma de Importe
A4: 102 | B4: 2196758.4
A5: 103 | B5: 2353365.8
A6: 104 | B6: 1157973.4
A7: 105 | B7: 1222388.4
A8: 107 | B8: 2368929.1
A9: 110 | B9: 1481362.1
A10: 111 | B10: 1123178
A11: 113 | B11: 1107858.1
A12: 114 | B12: 2319419.4
A13: 115 | B13: 918062.58
A14: 116 | B14: 381605.35
A15: 117 | B15: 1407771.9
... A58: 964 | B58: 259924.96
A59: (en blanco)
A60: 962 | B60: 27226.89
A61: 717 | B61: 83047.56
A62: 963 | B62: 18151.26
A63: NA | B63: 31890.058
A64: NA393 | B64: 4459632
A65: Total general | B65: 59126134

Sheet VENTAS DIARIAS
A3: Etiquetas de fila | B3: Suma de VALOR
A4: BARRANQUILLA | B4: 8477446
A5: BOGOTA | B5: 1.0471416e+08
A6: BUCARAMANGA | B6: 5520242.7
A7: CARTAGENA | B7: 9518644.9
A8: CUCUTA | B8: 6133455
A9: MEDELLIN | B9: 39305972
A10: MONTERIA | B10: 9597948.8
A11: PEREIRA | B11: 4385013.7
A12: VALLEDUPAR | B12: 5841956.6
A13: VILLAVICENCIO | B13: 42613562
A14: (en blanco)
A15: CALI | B15: 3220678.5
A16: Total general | B16: 2.3932908e+08

Sheet VENTAS POR VENDEDOR
A3: Etiquetas de fila | B3: Suma de VALOR
A4: 102 | B4: 2488032.7
A5: 103 | B5: 2817486.2
A6: 104 | B6: 12603370
A7: 105 | B7: 1956639.5
A8: 107 | B8: 6018575.7
A9: 110 | B9: 31932.916
A10: 111 | B10: 4359844.1
A11: 113 | B11: 1530633.1
A12: 114 | B12: 3095342.5
A13: 115 | B13: 1435139.7
A14: 116 | B14: 961643.3
A15: 117 | B15: 2007332.3
... A58: 964 | B58: 12882190
A59: (en blanco)
A60: 711 | B60: 33475.63
A61: 621 | B61: 26722.681
A62: Total general | B62: 2.3932908e+08

Sheet PEDIDOS POR VENDEDOR
D2: Etiquetas de fila | E2: Cuenta de PEDIDO TUTI
D3: 102 | E3: 91
D4: 103 | E4: 91
D5: 104 | E5: 139
D6: 105 | E6: 63
D7: 107 | E7: 140
D8: 110 | E8: 1
D9: 111 | E9: 68
B10: Etiquetas de fila | C10: Cuenta de VENDEDOR | D10: 113 | E10: 58
B11: BARRANQUILLA | C11: 158 | D11: 114 | E11: 81
B12: BOGOTA | C12: 1991 | D12: 115 | E12: 44
B13: BUCARAMANGA | C13: 126 | D13: 116 | E13: 32
B14: CARTAGENA | C14: 165 | D14: 117 | E14: 75
B15: CUCUTA | C15: 237 | D15: 405 | E15: 65
B16: MEDELLIN | C16: 881 | D16: 407 | E16: 29
B17: MONTERIA | C17: 172 | D17: 409 | E17: 89
B18: PEREIRA | C18: 69 | D18: 410 | E18: 27
B19: VALLEDUPAR | C19: 143 | D19: 411 | E19: 72
B20: VILLAVICENCIO | C20: 483 | D20: 413 | E20: 76
B21: (en blanco) | D21: 415 | E21: 9
B22: CALI | C22: 49 | D22: 509 | E22: 79
B23: Total general | C23: 4474 | D23: 510 | E23: 65
D24: 605 | E24: 55
D25: 612 | E25: 42
D26: 620 | E26: 48
D27: 705 | E27: 97
D28: 706 | E28: 46
D29: 712 | E29: 12
D30: 713 | E30: 46
D31: 714 | E31: 10
D32: 715 | E32: 25
D33: 717 | E33: 18
D34: 718 | E34: 147
D35: 720 | E35: 64
... D57: 964 | E57: 143
D58: (en blanco)
D59: 711 | E59: 1
D60: 621 | E60: 1
D61: Total general | E61: 4480

Sheet ENERO-25
A1: EJECUCIÓN MES
B3: DIAS CALENDARIO TRONEX | C3: DIAS TRANSCURRIDOS
A4: DIAS HABILES MES | B4: 15 | C4: 15
A6: GENERALES | B6: META MES | C6: ACUMULADO | D6: CUMPLIMIENTO | E6: VAR
A7: VENTAS | B7: 377404375 | C7: =407518760.260001/1.19 -> 3.4245274e+08 | D7: =+C7/B7 -> 0.90738943 | E7: =+C7/B7-1 -> -0.092610573
A8: PEDIDOS | B8: 6506.972 | C8: 6359 | D8: =+C8/B8 -> 0.97725947 | E8: =+C8/B8-1 -> -0.022740529
A9: TICKET PROMEDIO | B9: 58000 | C9: 64085.353 | D9: =+C9/B9 -> 1.1049199 | E9: =+C9/B9-1 -> 0.10491988
A10: CLIENTE | B10: 4972 | C10: 6099 | D10: =+C10/B10 -> 1.2266693 | E10: =+C10/B10-1 -> 0.22666935
A11: FRECUENCIA DE COMPRA | B11: 1.3 | C11: 1.0426299 | D11: =+C11/B11 -> 0.80202303 | E11: =+C11/B11-1 -> -0.19797697
B13: 2024 | C13: 2025 ACUMULADO ENERO/31 | D13: Var
A14: Ventas | B14: 280184625 | C14: 4.0751876e+08 | D14: 0.45446511
A15: Pedidos | B15: 4701 | C15: 6359 | D15: 0.35269092
A16: Ticket promedio | B16: 59601.069 | C16: 64085.353 | D16: 0.075238318
A17: Clientes | B17: 4446 | C17: 6099 | D17: 0.37179487
A18: Frecuencia de compra promedio | B18: 1.0573549 | C18: 1.0426299 | D18: -0.013926248
A20: EJECUCIÓN MES REGIONAL
B22: VENDEDORES | C22: % VENTA | D22: VENTA MES | E22: VENTAS X VENDEDOR | F22: VENTA ACUMULADA MES | G22: % VENTA MES | H22: PEDIDOS MES | I22: PEDIDOS X VENDEDOR | J22: PEDIDOS ACUMULADOS MES | K22: % PEDIDOS MES | L22: TICKET PROMEDIO ACUMULADO
A23: BOGOTA | B23: 19 | C23: 0.38 | D23: =+C23*$B$7 -> 1.4341366e+08 | E23: =+D23/B23 -> 7548087.5 | F23: 1.204757e+08 | G23: =+F23/$F$36 -> 0.29563228 | H23: 2472.6494 | I23: =+H23/B23 -> 130.13944 | J23: 2568 | K23: =+J23/$J$36 -> 0.40383708 | L23: =+F23/J23 -> 46914.214 | M23: 8.6759626
A24: MEDELLIN TAT | B24: 12 | C24: 0.265 | D24: =+C24*$B$7 -> 1.0001216e+08 | E24: =+D24/B24 -> 8334346.6 | F24: 96302922 | G24: =+F24/$F$36 -> 0.23631531 | H24: 1724.3476 | I24: =+H24/B24 -> 143.69563 | J24: 1010 | K24: =+J24/$J$36 -> 0.15883 | L24: =+F24/J24 -> 95349.428 | M24: 9.5797088
A25: MEDELLIN TUTI | B25: 2 | C25: 0.045 | D25: =+C25*$B$7 -> 16983197 | E25: =+D25/B25 -> 8491598.4 | F25: 30072320 | G25: =+F25/$F$36 -> 0.073793707 | H25: 292.81374 | I25: =+H25/B25 -> 146.40687 | J25: 486 | K25: =+J25/$J$36 -> 0.076427111 | L25: =+F25/J25 -> 61877.202 | M25: 9.760458
A26: VILLAVICENCIO | B26: 2 | C26: 0.04 | D26: =+C26*$B$7 -> 15096175 | E26: =+D26/B26 -> 7548087.5 | F26: 36059753 | G26: =+F26/$F$36 -> 0.088486119 | H26: 260.27888 | I26: =+H26/B26 -> 130.13944 | J26: 504 | K26: =+J26/$J$36 -> 0.079257745 | L26: =+F26/J26 -> 71547.13 | M26: 8.6759626
A27: CALI | B27: 2 | C27: 0.04 | D27: =+C27*$B$7 -> 15096175 | E27: =+D27/B27 -> 7548087.5 | F27: 31900625 | G27: =+F27/$F$36 -> 0.078280138 | H27: 260.27888 | I27: =+H27/B27 -> 130.13944 | J27: 412 | K27: =+J27/$J$36 -> 0.064790061 | L27: =+F27/J27 -> 77428.701 | M27: 8.6759626
A28: PEREIRA | B28: 2 | C28: 0.04 | D28: =+C28*$B$7 -> 15096175 | E28: =+D28/B28 -> 7548087.5 | F28: 4937720.1 | G28: =+F28/$F$36 -> 0.012116547 | H28: 260.27888 | I28: =+H28/B28 -> 130.13944 | J28: 55 | K28: =+J28/$J$36 -> 0.0086491587 | L28: =+F28/J28 -> 89776.729 | M28: 8.6759626
A29: BARRANQUILLA | B29: 6 | C29: 0.04 | D29: =+C29*$B$7 -> 15096175 | E29: =+D29/B29 -> 2516029.2 | F29: 9752581.3 | G29: =+F29/$F$36 -> 0.023931613 | H29: 260.27888 | I29: =+H29/B29 -> 43.379813 | J29: 98 | K29: =+J29/$J$36 -> 0.015411228 | L29: =+F29/J29 -> 99516.136 | M29: 2.8919875
A30: BUCARAMANGA | B30: 5 | C30: 0.04 | D30: =+C30*$B$7 -> 15096175 | E30: =+D30/B30 -> 3019235 | F30: 15350097 | G30: =+F30/$F$36 -> 0.037667215 | H30: 260.27888 | I30: =+H30/B30 -> 52.055776 | J30: 294 | K30: =+J30/$J$36 -> 0.046233685 | L30: =+F30/J30 -> 52211.214 | M30: 3.4703851
A31: CARTAGENA | B31: 2 | C31: 0.025 | D31: =+C31*$B$7 -> 9435109.4 | E31: =+D31/B31 -> 4717554.7 | F31: 15783374 | G31: =+F31/$F$36 -> 0.038730423 | H31: 162.6743 | I31: =+H31/B31 -> 81.33715 | J31: 229 | K31: =+J31/$J$36 -> 0.036011952 | L31: =+F31/J31 -> 68923.03 | M31: 5.4224767
A32: VALLEDUPAR | B32: 2 | C32: 0.02 | D32: =+C32*$B$7 -> 7548087.5 | E32: =+D32/B32 -> 3774043.8 | F32: 25830913 | G32: =+F32/$F$36 -> 0.063385825 | H32: 130.13944 | I32: =+H32/B32 -> 65.06972 | J32: 380 | K32: =+J32/$J$36 -> 0.059757824 | L32: =+F32/J32 -> 67976.087 | M32: 4.3379813
A33: CUCUTA | B33: 4 | C33: 0.03 | D33: =+C33*$B$7 -> 11322131 | E33: =+D33/B33 -> 2830532.8 | F33: 9227676.9 | G33: =+F33/$F$36 -> 0.022643563 | H33: 195.20916 | I33: =+H33/B33 -> 48.80229 | J33: 219 | K33: =+J33/$J$36 -> 0.034439377 | L33: =+F33/J33 -> 42135.511 | M33: 3.253486
A34: MONTERIA | B34: 2 | C34: 0.025 | D34: =+C34*$B$7 -> 9435109.4 | E34: =+D34/B34 -> 4717554.7 | F34: 10543105 | G34: =+F34/$F$36 -> 0.025871458 | H34: 162.6743 | I34: =+H34/B34 -> 81.33715 | J34: 84 | K34: =+J34/$J$36 -> 0.013209624 | L34: =+F34/J34 -> 125513.15 | M34: 5.4224767
A35: CLIENTE | B35: 0 | C35: 0.01 | D35: =+C35*$B$7 -> 3774043.8 | E35: =+D35/B35 -> #DIV/0! | F35: 1281972.4 | G35: =+F35/$F$36 -> 0.0031457996 | H35: 65.06972 | J35: 20 | K35: =+J35/$J$36 -> 0.0031451486 | L35: =+F35/J35 -> 64098.618 | M35: 0
A36: TOTAL | B36: =+B23+B24+B25+B26+B27+B28+B29+B30+B31+B32+B33+B34+B35 -> 60 | C36: =+C23+C24+C25+C26+C27+C28+C29+C30+C31+C32+C33+C34+C35 -> 1 | D36: =+D23+D24+D25+D26+D27+D28+D29+D30+D31+D32+D33+D34+D35 -> 377404375 | E36: =+D36/B36 -> 6290072.9 | F36: =+F23+F24+F25+F26+F27+F28+F29+F30+F31+F32+F33+F34+F35 -> 4.0751876e+08 | G36: 1 | H36: =+H23+H24+H25+H26+H27+H28+H29+H30+H31+H32+H33+H34+H35 -> 6506.972 | I36: =+I23+I24+I25+I26+I27+I28+I29+I30+I31+I32+I33+I34+I35 -> 1182.6422 | J36: =+J23+J24+J25+J26+J27+J28+J29+J30+J31+J32+J33+J34+J35 -> 6359 | K36: 1 | L36: =+F36/J36 -> 64085.353
B38: VENTA ENERO | C38: % VENTA | D38: CUMPL VENTA ENERO | E38: PEDIDO ENERO | F38: % PEDIDOS | G38: CUMPL PEDIDOS ENERO | H38: TICKET PROMEDIO
A39: MEDELLIN TAT | B39: =96302922/1.19 -> 80926825 | C39: =+B39/$B$52 -> 0.23631531 | D39: =+B39/D24 -> 0.80916986 | E39: =+J24 -> 1010 | F39: =+E39/$E$52 -> 0.15883 | G39: =+E39/H24 -> 0.58572878 | H39: =+B39/E39 -> 80125.57
A40: MEDELLIN TUTI | B40: =30072320/1.19 -> 25270857 | C40: =+B40/$B$52 -> 0.073793707 | D40: =+B40/D25 -> 1.4879918 | E40: =+J25 -> 486 | F40: =+E40/$E$52 -> 0.076427111 | G40: =+E40/H25 -> 1.6597582 | H40: =+B40/E40 -> 51997.648
A41: BOGOTA | B41: =120475701/1.19 -> 1.0124008e+08 | C41: =+B41/$B$52 -> 0.29563228 | D41: =+B41/D23 -> 0.70593054 | E41: =+J23 -> 2568 | F41: =+E41/$E$52 -> 0.40383708 | G41: =+E41/H23 -> 1.0385621 | H41: =+B41/E41 -> 39423.709
A42: VILLAVICENCIO | B42: =36059753/1.19 -> 30302313 | C42: =+B42/$B$52 -> 0.088486118 | D42: =+B42/D26 -> 2.0072842 | E42: =+J26 -> 504 | F42: =+E42/$E$52 -> 0.079257745 | G42: =+E42/H26 -> 1.9363845 | H42: =+B42/E42 -> 60123.638
A43: CALI | B43: =31900625/1.19 -> 26807248 | C43: =+B43/$B$52 -> 0.078280139 | D43: =+B43/D27 -> 1.7757643 | E43: =+J27 -> 412 | F43: =+E43/$E$52 -> 0.064790061 | G43: =+E43/H27 -> 1.5829175 | H43: =+B43/E43 -> 65066.136
A44: PEREIRA | B44: =+F28/1.19 -> 4149344.6 | C44: =+B44/$B$52 -> 0.012116547 | D44: =+B44/D28 -> 0.27486066 | E44: =+J28 -> 55 | F44: =+E44/$E$52 -> 0.0086491587 | G44: =+E44/H28 -> 0.21131181 | H44: =+B44/E44 -> 75442.63
A45: BARRANQUILLA | B45: =+F29/1.19 -> 8195446.5 | C45: =+B45/$B$52 -> 0.023931613 | D45: =+B45/D29 -> 0.54288232 | E45: =+J29 -> 98 | F45: =+E45/$E$52 -> 0.015411228 | G45: =+E45/H29 -> 0.37651922 | H45: =+B45/E45 -> 83627.005
A46: CARTAGENA | B46: =+F31/1.19 -> 13263339 | C46: =+B46/$B$52 -> 0.038730423 | D46: =+B46/D31 -> 1.405743 | E46: =+J31 -> 229 | F46: =+E46/$E$52 -> 0.036011952 | G46: =+E46/H31 -> 1.4077208 | H46: =+B46/E46 -> 57918.513
...

Sheet FEBRERO-25
A1: EJECUCIÓN MES
B3: DIAS CALENDARIO TRONEX | C3: DIAS TRANSCURRIDOS
A4: DIAS HABILES MES | B4: 20 | C4: 20
A6: GENERALES | B6: 2024 | C6: META MES | D6: ACUMULADO | E6: CUMPLIMIENTO | F6: CUMPL PROY | G6: Var
A7: VENTAS | B7: 364874472 | C7: 409705313 | D7: =583061587.720001/1.19 -> 4.8996772e+08 | E7: =+D7/C7 -> 1.1959028 | F7: =+D7/C7 -> 1.1959028 | G7: =+D7/B7-1 -> 0.34283914
A8: PEDIDOS | B8: 6379 | C8: 6303.1587 | D8: 10009 | E8: =+D8/C8 -> 1.587934 | F8: =+D8/C8 -> 1.587934 | G8: =+D8/B8-1 -> 0.56905471
A9: TICKET PROMEDIO | B9: 57199.322 | C9: 65000 | D9: 58253.73 | E9: =+D9/C9 -> 0.89621124 | F9: =+D9/C9 -> 0.89621124 | G9: =+D9/B9-1 -> 0.018433941
A10: CLIENTE | B10: 5790 | C10: 8194.1063 | D10: 8921 | E10: =+D10/C10 -> 1.0887093 | F10: =+D10/C10 -> 1.0887093 | G10: =+D10/B10-1 -> 0.54075993
A11: FRECUENCIA DE COMPRA | B11: =+B8/B10 -> 1.1017271 | C11: 1.3 | D11: 1.1219594 | E11: =+D11/C11 -> 0.86304571 | F11: =+D11/C11 -> 0.86304571 | G11: =+D11/B11-1 -> 0.018364172
A14: EJECUCIÓN MES REGIONAL
B16: VENDEDORES | C16: % VENTA | D16: VENTA MES | E16: VENTAS X VENDEDOR | F16: VENTA ACUMULADA MES | G16: % VENTA MES | H16: PEDIDOS MES | I16: PEDIDOS X VENDEDOR | J16: PEDIDOS ACUMULADOS MES | K16: % PEDIDOS MES | L16: TICKET PROMEDIO ACUMULADO
A17: BOGOTA | B17: 19 | C17: 0.38 | D17: 1.5568802e+08 | E17: 8194106.3 | F17: 1.9658891e+08 | G17: 0.33716662 | H17: =+C17*$C$8 -> 2395.2003 | I17: 126.06317 | J17: 4159 | K17: 0.41552603 | L17: 47268.311 | M17: 6.3031587 | O17: 33264304 | P17: =+O17/F17 -> 0.16920743
A18: MEDELLIN TAT | B18: 12 | C18: 0.265 | D18: 1.0857191e+08 | E18: 9047659 | F18: 1.3699651e+08 | G18: 0.23496061 | H18: =+C18*$C$8 -> 1670.337 | I18: 139.19475 | J18: 1955 | K18: 0.19532421 | L18: 70074.94 | M18: 6.9597377
A19: MEDELLIN TUTI | B19: 2 | C19: 0.045 | D19: 18436739 | E19: 9218369.5 | F19: 17911213 | G19: 0.030719247 | H19: =+C19*$C$8 -> 283.64214 | I19: 141.82107 | J19: 403 | K19: 0.040263763 | L19: 44444.697 | M19: 7.0910535
A20: VILLAVICENCIO | B20: 2 | C20: 0.04 | D20: 16388213 | E20: 8194106.3 | F20: 43508200 | G20: 0.074620248 | H20: =+C20*$C$8 -> 252.12635 | I20: 126.06317 | J20: 644 | K20: 0.064342092 | L20: 67559.317 | M20: 6.3031587
A21: CALI | B21: 2 | C21: 0.04 | D21: 16388213 | E21: 8194106.3 | F21: 35606134 | G21: 0.061067535 | H21: =+C21*$C$8 -> 252.12635 | I21: 126.06317 | J21: 552 | K21: 0.055150365 | L21: 64503.866 | M21: 6.3031587
A22: PEREIRA | B22: 2 | C22: 0.04 | D22: 16388213 | E22: 8194106.3 | F22: 8757058.7 | G22: 0.015019097 | H22: =+C22*$C$8 -> 252.12635 | I22: 126.06317 | J22: 117 | K22: 0.011689479 | L22: 74846.655 | M22: 6.3031587
A23: BARRANQUILLA | B23: 6 | C23: 0.04 | D23: 16388213 | E23: 2731368.8 | F23: 24975223 | G23: 0.042834622 | H23: =+C23*$C$8 -> 252.12635 | I23: 42.021058 | J23: 278 | K23: 0.027775002 | L23: 89838.93 | M23: 2.1010529
A24: CUCUTA | B24: 3 | C24: 0.03 | D24: 12291159 | E24: 4097053.1 | F24: 8569209.1 | G24: 0.014696919 | H24: =+C24*$C$8 -> 189.09476 | I24: 63.031587 | J24: 186 | K24: 0.018583275 | L24: 46071.017 | M24: 3.1515793
A25: CARTAGENA | B25: 2 | C25: 0.025 | D25: 10242633 | E25: 5121316.4 | F25: 27698596 | G25: 0.047505437 | H25: =+C25*$C$8 -> 157.57897 | I25: 78.789483 | J25: 422 | K25: 0.042162054 | L25: 65636.483 | M25: 3.9394742
A26: VALLEDUPAR | B26: 2 | C26: 0.02 | D26: 8194106.3 | E26: 4097053.1 | F26: 36861189 | G26: 0.063220061 | H26: =+C26*$C$8 -> 126.06317 | I26: 63.031587 | J26: 632 | K26: 0.063143171 | L26: 58324.667 | M26: 3.1515793
A27: BUCARAMANGA | B27: 4 | C27: 0.04 | D27: 16388213 | E27: 4097053.1 | F27: 26855651 | G27: 0.046059716 | H27: =+C27*$C$8 -> 252.12635 | I27: 63.031587 | J27: 486 | K27: 0.048556299 | L27: 55258.542 | M27: 3.1515793
A28: MONTERIA | B28: 2 | C28: 0.025 | D28: 10242633 | E28: 5121316.4 | F28: 17190575 | G28: 0.029483291 | H28: =+C28*$C$8 -> 157.57897 | I28: 78.789483 | J28: 162 | K28: 0.016185433 | L28: 106114.66 | M28: 3.9394742
A29: CLIENTE | B29: 0 | C29: 0.01 | D29: 4097053.1 | F29: 1543124.2 | G29: =+F29/F30 -> 0.0026465887 | H29: =+C29*$C$8 -> 63.031587 | I29: 0 | J29: 13 | K29: 0.0012988311 | L29: 118701.86 | M29: 0
A30: TOTAL | B30: =+B17+B18+B19+B20+B21+B22+B23+B24+B25+B26+B27+B28+B29 -> 58 | C30: =+C17+C18+C19+C20+C21+C22+C23+C24+C25+C26+C27+C28+C29 -> 1 | D30: 4.0970531e+08 | E30: 76307615 | F30: 5.8306159e+08 | G30: 1 | H30: 6303.1587 | I30: 1173.9633 | J30: 10009 | K30: 1 | L30: 58253.73
B32: VENTA FEBRERO | C32: % | D32: CUMPLIMIENTO | E32: PEDIDOS FEBRERO | F32: %PEDIDOS | G32: CUMPLIMIENTO PEDIDOS | H32: TICKET PROMEDIO
A33: MEDELLIN TAT | B33: =136996508.43/1.19 -> 1.1512312e+08 | C33: 0.23496061 | D33: 1.2618044 | E33: 1955 | F33: 0.19532421 | G33: 1.1704225 | H33: 70074.94
A34: MEDELLIN TUTI | B34: =17911212.86/1.19 -> 15051439 | C34: 0.030719247 | D34: 0.97149571 | E34: 403 | F34: 0.040263763 | G34: 1.4208044 | H34: 44444.697
A35: BOGOTA | B35: =196588906.45/1.19 -> 1.6520076e+08 | C35: 0.33716662 | D35: 1.2627106 | E35: 4159 | F35: 0.41552603 | G35: 1.7363892 | H35: 47268.311
A36: VILLAVICENCIO | B36: =43508200.0400001/1.19 -> 36561513 | C36: 0.074620248 | D36: 2.6548472 | E36: 644 | F36: 0.064342092 | G36: 2.5542749 | H36: 67559.317
A37: CALI | B37: =35606134.03/1.19 -> 29921121 | C37: 0.061067535 | D37: 2.1726673 | E37: 552 | F37: 0.055150365 | G37: 2.1893785 | H37: 64503.866
A38: PEREIRA | B38: =8757058.65/1.19 -> 7358872.8 | C38: 0.015019097 | D38: 0.53435106 | E38: 117 | F38: 0.011689479 | G38: 0.46405305 | H38: 74846.655
A39: BARRANQUILLA | B39: =24975222.6000001/1.19 -> 20987582 | C39: 0.042834622 | D39: 1.5239748 | E39: 278 | F39: 0.027775002 | G39: 1.1026218 | H39: 89838.93
A40: CARTAGENA | B40: =27698595.7600001/1.19 -> 23276131 | C40: 0.047505437 | D40: 2.7042457 | E40: 422 | F40: 0.042162054 | G40: 2.6780224 | H40: 65636.483
A41: VALLEDUPAR | B41: =36861189.4300001/1.19 -> 30975789 | C41: 0.063220061 | D41: 4.4985003 | E41: 632 | F41: 0.063143171 | G41: 5.0133594 | H41: 58324.667
A42: BUCARAMANGA | B42: =26855651.37/1.19 -> 22567774 | C42: 0.046059716 | D42: 1.6387175 | E42: 486 | F42: 0.048556299 | G42: 1.927605 | H42: 55258.542
A43: CUCUTA | B43: =8569209.15/1.19 -> 7201016.1 | C43: 0.014696919 | D43: 0.69718477 | E43: 186 | F43: 0.018583275 | G43: 0.98363381 | H43: 46071.017
A44: MONTERIA | B44: =17190574.73/1.19 -> 14445861 | C44: 0.029483291 | D44: 1.6783355 | E44: 162 | F44: 0.016185433 | G44: 1.028056 | H44: 106114.66
A45: CLIENTE | B45: =1543124.22/1.19 -> 1296743 | C45: 0.0026465887 | D45: 0.37664247 | E45: 13 | F45: 0.0012988311 | G45: 0.2062458 | H45: 118701.86
A46: TOTAL | B46: =583061587.720001/1.19 -> 4.8996772e+08 | C46: 1 | D46: 1.4231243 | E46: 10009 | F46: 1 | G46: 1.587934 | H46: 58253.73
...

Sheet MARZO-25
A1: EJECUCIÓN MES
B3: DIAS CALENDARIO TRONEX | C3: DIAS TRANSCURRIDOS
A4: DIAS HABILES MES | B4: 19 | C4: 19
A6: GENERALES | B6: 2024 | C6: META MES | D6: ACUMULADO | E6: CUMPLIMIENTO | F6: CUMPL PROY | G6: Var
A7: VENTAS | B7: 269027773 | C7: 385605000 | D7: =520044549.87/1.19 -> 4.3701223e+08 | E7: =+D7/C7 -> 1.1333158 | F7: =+D7/C7 -> 1.1333158 | G7: =+D7/B7-1 -> 0.62441306
A8: PEDIDOS | B8: 4924 | C8: 6426.75 | D8: 8927 | E8: =+D8/C8 -> 1.389038 | F8: =+D8/C8 -> 1.389038 | G8: =+D8/B8-1 -> 0.81295695
A9: TICKET PROMEDIO | B9: 54636.022 | C9: 60000 | D9: 58255.243 | E9: =+D9/C9 -> 0.97092071 | F9: =+D9/C9 -> 0.97092071 | G9: =+D9/B9-1 -> 0.066242384
A10: CLIENTE | B10: 4646 | C10: 7069.425 | D10: 7743 | E10: =+D10/C10 -> 1.09528 | F10: =+D10/C10 -> 1.09528 | G10: =+D10/B10-1 -> 0.66659492
A11: FRECUENCIA DE COMPRA | B11: =+B8/B10 -> 1.0598364 | C11: 1.1 | D11: 1.1 | E11: =+D11/C11 -> 1 | F11: =+D11/C11 -> 1 | G11: =+D11/B11-1 -> 0.037896019
A14: EJECUCIÓN MES REGIONAL
B16: VENDEDORES | C16: % VENTA | D16: VENTA MES | E16: VENTAS X VENDEDOR | F16: VENTA ACUMULADA MES | G16: % VENTA MES | H16: PEDIDOS MES | I16: PEDIDOS X VENDEDOR | J16: PEDIDOS ACUMULADOS MES | K16: % PEDIDOS MES | L16: TICKET PROMEDIO ACUMULADO
A17: BOGOTA | B17: 19 | C17: 0.38 | D17: 146529900 | E17: 7712100 | F17: 1.7776194e+08 | G17: 0.3418206 | H17: 2442.165 | I17: 128.535 | J17: 3830 | K17: 0.42903551 | L17: 46413.039 | N17: 6.765
A18: MEDELLIN | B18: 13 | C18: 0.31 | D18: 119537550 | E18: 9195196.2 | F18: 1.1387617e+08 | G18: 0.21897387 | H18: 1992.2925 | I18: 153.25327 | J18: 1530 | K18: 0.17139016 | L18: 74428.867 | N18: 8.0659615
A19: BARRANQUILLA | B19: 6 | C19: 0.04 | D19: 15424200 | E19: 2570700 | F19: 30213155 | G19: 0.058097244 | H19: 257.07 | I19: 42.845 | J19: 389 | K19: 0.043575669 | L19: 77668.78 | N19: 2.255
A20: BUCARAMANGA | B20: 4 | C20: 0.04 | D20: 15424200 | E20: 3856050 | F20: 32735315 | G20: 0.062947136 | H20: 257.07 | I20: 64.2675 | J20: 537 | K20: 0.060154587 | L20: 60959.619 | N20: 3.3825
A21: CUCUTA | B21: 3 | C21: 0.03 | D21: 11568150 | E21: 3856050 | F21: 8175163.2 | G21: 0.015720121 | H21: 192.8025 | I21: 64.2675 | J21: 197 | K21: 0.022067884 | L21: 41498.29 | N21: 3.3825
A22: VILLAVICENCIO | B22: 2 | C22: 0.04 | D22: 15424200 | E22: 7712100 | F22: 36953245 | G22: 0.071057844 | H22: 257.07 | I22: 128.535 | J22: 524 | K22: 0.058698331 | L22: 70521.459 | N22: 6.765
A23: CALI | B23: 2 | C23: 0.04 | D23: 15424200 | E23: 7712100 | F23: 48153699 | G23: 0.092595335 | H23: 257.07 | I23: 128.535 | J23: 704 | K23: 0.07886188 | L23: 68400.141 | N23: 6.765
A24: PEREIRA | B24: 2 | C24: 0.04 | D24: 15424200 | E24: 7712100 | F24: 13106506 | G24: 0.02520266 | H24: 257.07 | I24: 128.535 | J24: 226 | K24: 0.025316456 | L24: 57993.39 | N24: 6.765
A25: CARTAGENA | B25: 2 | C25: 0.025 | D25: 9640125 | E25: 4820062.5 | F25: 21306567 | G25: 0.040970657 | H25: 160.66875 | I25: 80.334375 | J25: 355 | K25: 0.039766999 | L25: 60018.498 | N25: 4.228125
A26: VALLEDUPAR | B26: 2 | C26: 0.02 | D26: 7712100 | E26: 3856050 | F26: 26692430 | G26: 0.051327198 | H26: 128.535 | I26: 64.2675 | J26: 503 | K26: 0.056345917 | L26: 53066.46 | N26: 3.3825
A27: MONTERIA | B27: 2 | C27: 0.025 | D27: 9640125 | E27: 4820062.5 | F27: 10104600 | G27: 0.019430259 | H27: 160.66875 | I27: 80.334375 | J27: 117 | K27: 0.013106307 | L27: 86364.106 | N27: 4.228125
A28: CLIENTE | B28: 0 | C28: 0.01 | D28: 3856050 | F28: 965764.17 | G28: 0.0018570797 | H28: 64.2675 | J28: 15 | K28: 0.0016802957 | L28: 64384.278 | N28: 0
A29: TOTAL | B29: 57 | C29: 1 | D29: 385605000 | E29: 63822571 | F29: 5.2004455e+08 | G29: 1 | H29: 6426.75 | I29: 1063.7095 | J29: 8927 | K29: 1 | L29: 58255.243
B31: VENTA MARZO | C31: % | D31: CUMPLIMIENTO PROYECTADO | E31: PEDIDOS PROYECTADOS | F31: %PEDIDOS | G31: CUMPLIMIENTO PROYECTADO | H31: TICKET PROMEDIO
A32: BOGOTA | B32: =177761938.27/1.19 -> 1.4937978e+08 | C32: 0.3418206 | D32: 1.2131445 | E32: 3830 | F32: 0.42903551 | G32: 1.5682806 | H32: 46413.039
A33: MEDELLIN | B33: =113876167.15/1.19 -> 95694258 | C33: 0.21897387 | D33: 0.95263929 | E33: 1530 | F33: 0.17139016 | G33: 0.76795952 | H33: 74428.867
A34: BARRANQUILLA | B34: =30213155.2800001/1.19 -> 25389206 | C34: 0.058097244 | D34: 1.9588151 | E34: 389 | F34: 0.043575669 | G34: 1.5132065 | H34: 77668.78
A35: BUCARAMANGA | B35: =32735315.25/1.19 -> 27508668 | C35: 0.062947136 | D35: 2.1223347 | E35: 537 | F35: 0.060154587 | G35: 2.0889252 | H35: 60959.619
A36: CUCUTA | B36: =8175163.19/1.19 -> 6869885 | C36: 0.015720121 | D36: 0.70669581 | E36: 197 | F36: 0.022067884 | G36: 1.021771 | H36: 41498.29
A37: VILLAVICENCIO | B37: =36953244.68/1.19 -> 31053147 | C37: 0.071057844 | D37: 2.3957965 | E37: 524 | F37: 0.058698331 | G37: 2.0383553 | H37: 70521.459
A38: CALI | B38: =48153699.24/1.19 -> 40465293 | C38: 0.092595335 | D38: 3.1219577 | E38: 704 | F38: 0.07886188 | G38: 2.7385537 | H38: 68400.141
A39: PEREIRA | B39: =13106506.05/1.19 -> 11013871 | C39: 0.02520266 | D39: 0.84973652 | E39: 226 | F39: 0.025316456 | G39: 0.87913798 | H39: 57993.39
A40: CARTAGENA | B40: =21306566.63/1.19 -> 17904678 | C40: 0.040970657 | D40: 2.2101961 | E40: 355 | F40: 0.039766999 | G40: 2.2095149 | H40: 60018.498
A41: VALLEDUPAR | B41: =26692429.5/1.19 -> 22430613 | C41: 0.051327198 | D41: 3.4611104 | E41: 503 | F41: 0.056345917 | G41: 3.913331 | H41: 53066.46
A42: MONTERIA | B42: =10104600.46/1.19 -> 8491260.9 | C42: 0.019430259 | D42: 1.0481815 | E42: 117 | F42: 0.013106307 | G42: 0.72820633 | H42: 86364.106
A43: CLIENTE | B43: =965764.17/1.19 -> 811566.53 | C43: 0.0018570797 | D43: 0.25045427 | E43: 15 | F43: 0.0016802957 | G43: 0.23339946 | H43: 64384.278
A44: TOTAL | B44: =+SUM(B32:B43) -> 4.3701223e+08 | C44: 1 | D44: 1.3486458 | E44: 8927 | F44: 1 | G44: 1.389038 | H44: 58255.243
A46: EJECUCIÓN MES X VENDEDOR
A48: SUPERVISOR | B48: REGIONAL | C48: VENDEDOR | D48: META PEDIDOS MES | E48: PEDIDOS ACUMULADOS MES | F48: VENTA ACUMULADA | G48: CUMPL PEDIDOS | H48: PEDIDOS DIARIOS | I48: >
...

Sheet ABRIL-25 
A1: EJECUCIÓN MES
B3: DIAS CALENDARIO TRONEX | C3: DIAS TRANSCURRIDOS
A4: DIAS HABILES MES | B4: 18 | C4: 18
A6: GENERALES | B6: 2024 | C6: META MES | D6: ACUMULADO | E6: CUMPLIMIENTO | F6: CUMPL PROY | G6: Var
A7: VENTAS | B7: 280184624 | C7: 337404375 | D7: =455785325.390001/1.19 -> 3.8301288e+08 | E7: =+D7/C7 -> 1.1351746 | F7: =+D7/C7 -> 1.1351746 | G7: =+D7/C7-1 -> 0.13517461
A8: PEDIDOS | B8: 4701.0054 | C8: 5623.4062 | D8: 7740 | E8: =+D8/C8 -> 1.37639 | F8: =+D8/C8 -> 1.37639 | G8: =+D8/C8-1 -> 0.37638998
A9: TICKET PROMEDIO | B9: 59601 | C9: 60000 | D9: 58886.993 | E9: =+D9/C9 -> 0.98144988 | F9: =+D9/C9 -> 0.98144988 | G9: =+D9/C9-1 -> -0.018550118
A10: CLIENTE | B10: 4708 | C10: 6185.7469 | D10: 7007 | E10: =+D10/C10 -> 1.1327654 | F10: =+D10/C10 -> 1.1327654 | G10: =+D10/C10-1 -> 0.13276539
A11: FRECUENCIA DE COMPRA | B11: =+B8/B10 -> 0.99851432 | C11: 1.1 | D11: 1.1 | E11: =+D11/C11 -> 1 | F11: =+D11/C11 -> 1 | G11: =+D11/C11-1 -> 0
A14: EJECUCIÓN MES REGIONAL
B16: VENDEDORES | C16: % VENTA | D16: VENTA MES | E16: VENTAS X VENDEDOR | F16: VENTA ACUMULADA MES | G16: % VENTA MES | H16: PEDIDOS MES | I16: PEDIDOS X VENDEDOR | J16: PEDIDOS ACUMULADOS MES | K16: % PEDIDOS MES | L16: TICKET PROMEDIO ACUMULADO
A17: BOGOTA | B17: 19 | C17: 0.38 | D17: 1.2821366e+08 | E17: 6748087.5 | F17: 1.7002817e+08 | G17: 0.37304442 | H17: 2136.8944 | I17: 112.46812 | J17: 3512 | K17: 0.45374677 | L17: 48413.488 | N17: 6.2482292
A18: MEDELLIN | B18: 13 | C18: 0.31 | D18: 1.0459536e+08 | E18: 8045796.6 | F18: 84592031 | G18: 0.18559621 | H18: 1743.2559 | I18: 134.09661 | J18: 1423 | K18: 0.18385013 | L18: 59446.262 | N18: 7.4498117
A19: BARRANQUILLA | B19: 6 | C19: 0.055 | D19: 18557241 | E19: 3092873.4 | F19: 38831692 | G19: 0.085197328 | H19: 309.28734 | I19: 51.547891 | J19: 585 | K19: 0.075581395 | L19: 66378.96 | N19: 2.8637717
A20: BUCARAMANGA | B20: 4 | C20: 0.04 | D20: 13496175 | E20: 3374043.8 | F20: 23790737 | G20: 0.052197242 | H20: 224.93625 | I20: 56.234063 | J20: 405 | K20: 0.052325581 | L20: 58742.56 | N20: 3.1241146
A21: CUCUTA | B21: 3 | C21: 0.03 | D21: 10122131 | E21: 3374043.8 | F21: 5825686.6 | G21: 0.012781646 | H21: 168.70219 | I21: 56.234063 | J21: 149 | K21: 0.019250646 | L21: 39098.568 | N21: 3.1241146
A22: VILLAVICENCIO | B22: 2 | C22: 0.04 | D22: 13496175 | E22: 6748087.5 | F22: 57774110 | G22: 0.12675728 | H22: 224.93625 | I22: 112.46813 | J22: 657 | K22: 0.084883721 | L22: 87936.24 | N22: 6.2482292
A23: CALI | B23: 2 | C23: 0.04 | D23: 13496175 | E23: 6748087.5 | F23: 21742874 | G23: 0.047704199 | H23: 224.93625 | I23: 112.46813 | J23: 261 | K23: 0.03372093 | L23: 83306.03 | N23: 6.2482292
A24: PEREIRA | B24: 2 | C24: 0.04 | D24: 13496175 | E24: 6748087.5 | F24: 12875931 | G24: 0.028249989 | H24: 224.93625 | I24: 112.46813 | J24: 174 | K24: 0.02248062 | L24: 73999.601 | N24: 6.2482292
A25: CARTAGENA | B25: 2 | C25: 0.02 | D25: 6748087.5 | E25: 3374043.8 | F25: 14865351 | G25: 0.032614808 | H25: 112.46813 | I25: 56.234063 | J25: 174 | K25: 0.02248062 | L25: 85433.05 | N25: 3.1241146
A26: VALLEDUPAR | B26: 2 | C26: 0.02 | D26: 6748087.5 | E26: 3374043.8 | F26: 16627458 | G26: 0.036480899 | H26: 112.46813 | I26: 56.234063 | J26: 317 | K26: 0.040956072 | L26: 52452.55 | N26: 3.1241146
A27: MONTERIA | B27: 2 | C27: 0.015 | D27: 5061065.6 | E27: 2530532.8 | F27: 8002092.5 | G27: 0.017556714 | H27: 84.351094 | I27: 42.175547 | J27: 73 | K27: 0.0094315245 | L27: 109617.71 | N27: 2.3430859
A28: CLIENTE | B28: 0 | C28: 0.01 | D28: 3374043.8 | F28: 829192.35 | G28: 0.0018192607 | H28: 56.234063 | J28: 10 | K28: 0.0012919897 | L28: 82919.235 | N28: 0
A29: TOTAL | B29: 57 | C29: 1 | D29: 337404375 | E29: 54157728 | F29: 4.5578533e+08 | G29: 1 | H29: 5623.4062 | I29: 902.6288 | J29: 7740 | K29: 1 | L29: 58886.993
B31: VENTA ABRIL | C31: % | D31: CUMPLIMIENTO PROYECTADO | E31: PEDIDOS PROYECTADOS | F31: %PEDIDOS | G31: CUMPLIMIENTO PROYECTADO | H31: TICKET PROMEDIO
A32: BOGOTA | B32: =170028171.07/1.19 -> 1.4288082e+08 | C32: 0.37304442 | D32: 1.3261315 | E32: 3512 | F32: 0.45374677 | G32: 1.6435066 | H32: 48413.488
A33: MEDELLIN | B33: =84592031.01/1.19 -> 71085740 | C33: 0.18559621 | D33: 0.80875513 | E33: 1423 | F33: 0.18385013 | G33: 0.81628863 | H33: 59446.262
A34: BARRANQUILLA | B34: =38831691.6400002/1.19 -> 32631674 | C34: 0.085197328 | D34: 2.0925359 | E34: 585 | F34: 0.075581395 | G34: 1.891445 | H34: 66378.96
A35: BUCARAMANGA | B35: =23790736.98/1.19 -> 19992216 | C35: 0.052197242 | D35: 1.7627763 | E35: 405 | F35: 0.052325581 | G35: 1.8005101 | H35: 58742.56
A36: CUCUTA | B36: =5825686.64/1.19 -> 4895535 | C36: 0.012781646 | D36: 0.57553953 | E36: 149 | F36: 0.019250646 | G36: 0.88321321 | H36: 39098.568
A37: VILLAVICENCIO | B37: =57774109.7/1.19 -> 48549672 | C37: 0.12675728 | D37: 4.2807766 | E37: 657 | F37: 0.084883721 | G37: 2.9208276 | H37: 87936.24
A38: CALI | B38: =21742873.89/1.19 -> 18271323 | C38: 0.047704199 | D38: 1.6110397 | E38: 261 | F38: 0.03372093 | G38: 1.1603288 | H38: 83306.03
A39: PEREIRA | B39: =12875930.52/1.19 -> 10820110 | C39: 0.028249989 | D39: 0.95404294 | E39: 174 | F39: 0.02248062 | G39: 0.77355251 | H39: 73999.601
A40: CARTAGENA | B40: =14865350.69/1.19 -> 12491891 | C40: 0.032614808 | D40: 2.2028983 | E40: 174 | F40: 0.02248062 | G40: 1.547105 | H40: 85433.05
A41: VALLEDUPAR | B41: =16627458.42/1.19 -> 13972654 | C41: 0.036480899 | D41: 2.4640253 | E41: 317 | F41: 0.040956072 | G41: 2.8185764 | H41: 52452.55
A42: MONTERIA | B42: =8002092.48/1.19 -> 6724447.5 | C42: 0.017556714 | D42: 1.5811082 | E42: 73 | F42: 0.0094315245 | G42: 0.86543039 | H42: 109617.71
A43: CLIENTE | B43: =829192.35/1.19 -> 696800.29 | C43: 0.0018192607 | D43: 0.24575625 | E43: 10 | F43: 0.0012919897 | G43: 0.17782816 | H43: 82919.235
A44: TOTAL | B44: =+SUM(B32:B43) -> 3.8301288e+08 | C44: 1 | D44: 1.3508578 | E44: 7740 | F44: 1 | G44: 1.37639 | H44: 58886.993
A46: EJECUCIÓN MES X VENDEDOR
A48: SUPERVISOR | B48: REGIONAL | C48: VENDEDOR | D48: META PEDIDOS MES | E48: PEDIDOS ACUMULADOS MES | F48: VENTA ACUMULADA | G48: CUMPL PROY | H48: PEDIDOS DIARIOS | I48: >
...

Sheet MAYO-25
A1: EJECUCIÓN MES
B3: DIAS CALENDARIO TRONEX | C3: DIAS TRANSCURRIDOS
A4: DIAS HABILES MES | B4: 20 | C4: 20
A6: GENERALES | B6: 2023 | C6: META MES | D6: ACUMULADO | E6: CUMPLIMIENTO | F6: CUMPLIMIENTO | G6: Var
A7: VENTAS | B7: 402585958 | C7: 409705313 | D7: =531266043.210001/1.19 -> 4.4644205e+08 | E7: =+D7/C7 -> 1.0896663 | F7: =+D7/C7 -> 1.0896663 | G7: =+D7/C7-1 -> 0.089666253
A8: PEDIDOS | B8: 7319.7447 | C8: 6828.4219 | D8: 8767 | E8: =+D8/C8 -> 1.2838984 | F8: =+D8/C8 -> 1.2838984 | G8: =+D8/C8-1 -> 0.28389841
A9: TICKET PROMEDIO | B9: 55000 | C9: 60000 | D9: 60598.385 | E9: =+D9/C9 -> 1.0099731 | F9: =+D9/C9 -> 1.0099731 | G9: =+D9/C9-1 -> 0.009973087
A10: CLIENTE | B10: 6476 | C10: 7511.2641 | D10: 7703 | E10: =+D10/C10 -> 1.0255265 | F10: =+D10/C10 -> 1.0255265 | G10: =+D10/C10-1 -> 0.025526453
A11: FRECUENCIA DE COMPRA | B11: =+B8/B10 -> 1.1302879 | C11: 1.1 | D11: 1.1 | E11: =+D11/C11 -> 1 | F11: =+D11/C11 -> 1 | G11: =+D11/C11-1 -> 0
A14: EJECUCIÓN MES REGIONAL
B16: VENDEDORES | C16: % VENTA | D16: VENTA MES | E16: VENTAS X VENDEDOR | F16: VENTA ACUMULADA MES | G16: % VENTA MES | H16: PEDIDOS MES | I16: PEDIDOS X VENDEDOR | J16: PEDIDOS ACUMULADOS MES | K16: % PEDIDOS MES | L16: TICKET PROMEDIO ACUMULADO
A17: BOGOTA | B17: 19 | C17: 0.38 | D17: 1.5568802e+08 | E17: 8194106.3 | F17: 1.9501207e+08 | G17: 0.36707046 | H17: 2594.8003 | I17: 136.56844 | J17: 3840 | K17: 0.43800616 | L17: 50784.393 | N17: 6.8284219
A18: MEDELLIN | B18: 13 | C18: 0.31 | D18: 1.2700865e+08 | E18: 9769895.9 | F18: 1.1957372e+08 | G18: 0.22507315 | H18: 2116.8108 | I18: 162.8316 | J18: 1688 | K18: 0.19254021 | L18: 70837.513 | N18: 8.1415799
A19: BARRANQUILLA | B19: 6 | C19: 0.055 | D19: 22533792 | E19: 3755632 | F19: 58433778 | G19: 0.10998967 | H19: 375.5632 | I19: 62.593867 | J19: 784 | K19: 0.089426258 | L19: 74532.88 | N19: 3.1296934
A20: BUCARAMANGA | B20: 4 | C20: 0.04 | D20: 16388213 | E20: 4097053.1 | F20: 21039349 | G20: 0.039602284 | H20: 273.13688 | I20: 68.284219 | J20: 387 | K20: 0.044142808 | L20: 54365.242 | N20: 3.4142109
A21: CUCUTA | B21: 3 | C21: 0.03 | D21: 12291159 | E21: 4097053.1 | F21: 7517020.8 | G21: 0.014149259 | H21: 204.85266 | I21: 68.284219 | J21: 179 | K21: 0.020417475 | L21: 41994.529 | N21: 3.4142109
A22: VILLAVICENCIO | B22: 2 | C22: 0.04 | D22: 16388213 | E22: 8194106.3 | F22: 51767733 | G22: 0.097442201 | H22: 273.13688 | I22: 136.56844 | J22: 725 | K22: 0.082696475 | L22: 71403.769 | N22: 6.8284219
A23: CALI | B23: 2 | C23: 0.04 | D23: 16388213 | E23: 8194106.3 | F23: 15439083 | G23: 0.029060926 | H23: 273.13688 | I23: 136.56844 | J23: 202 | K23: 0.023040949 | L23: 76431.104 | N23: 6.8284219
A24: PEREIRA | B24: 2 | C24: 0.04 | D24: 16388213 | E24: 8194106.3 | F24: 13804010 | G24: 0.025983234 | H24: 273.13688 | I24: 136.56844 | J24: 210 | K24: 0.023953462 | L24: 65733.381 | N24: 6.8284219
A25: CARTAGENA | B25: 2 | C25: 0.02 | D25: 8194106.3 | E25: 4097053.1 | F25: 11016383 | G25: 0.020736095 | H25: 136.56844 | I25: 68.284219 | J25: 182 | K25: 0.020759667 | L25: 60529.577 | N25: 3.4142109
A26: VALLEDUPAR | B26: 2 | C26: 0.02 | D26: 8194106.3 | E26: 4097053.1 | F26: 22895353 | G26: 0.043095833 | H26: 136.56844 | I26: 68.284219 | J26: 417 | K26: 0.047564731 | L26: 54904.923 | N26: 3.4142109
A27: MONTERIA | B27: 2 | C27: 0.015 | D27: 6145579.7 | E27: 3072789.8 | F27: 13542406 | G27: 0.025490817 | H27: 102.42633 | I27: 51.213164 | J27: 142 | K27: 0.016197103 | L27: 95369.054 | N27: 2.5606582
A28: CLIENTE | B28: 0 | C28: 0.01 | D28: 4097053.1 | F28: 1225136.6 | G28: 0.0023060698 | H28: 68.284219 | J28: 11 | K28: 0.0012547051 | L28: 111376.05 | N28: 0
A29: TOTAL | B29: 57 | C29: 1 | D29: 4.0970531e+08 | E29: 65762955 | F29: 5.3126604e+08 | G29: 1 | H29: 6828.4219 | I29: 1096.0493 | J29: 8767 | K29: 1 | L29: 60598.385
B31: VENTA MAYO | C31: % | D31: CUMPLIMIENTO | E31: PEDIDOS PROYECTADOS | F31: %PEDIDOS | G31: CUMPLIMIENTO PROYECTADO | H31: TICKET PROMEDIO
